Workbook
Name AREACOZINHA: '1 - Planta'!$F$16
Name AREAQUARTO: '1 - Planta'!$S$7
Name AREASALAESTAR: '1 - Planta'!$P$16
Name AREASUITEMASTER: '1 - Planta'!$F$6
Name AREAWC: '1 - Planta'!$L$6
Name PERIMCOSINHA: '1 - Planta'!$F$17
Name PERIMETROSALA: '1 - Planta'!$P$17
Name PERIMQUARTO: '1 - Planta'!$S$8
Name PERIMWC: '1 - Planta'!$L$7
Name PSUITEMASTER: '1 - Planta'!$F$7

Sheet 1 - Planta
F2: =COUNTBLANK(C8:J8)/2 -> 4 | L2: =COUNTBLANK(K11:M11)/2 -> 1.5 | N2: =COUNTBLANK(N11:P11)/2 -> 1.5 | Q2: =COUNTBLANK(Q10:V10)/2 -> 3
F4: J | L4: J | O4: J | T4: J
F5: SUÍTE MASTER | L5: WC Suíte | O5: WC Soc. | AA5: LEGENDA:
B6: =COUNTBLANK(C4:C10)/2 -> 3.5 | E6: Área: | F6: =B6*F2 -> 14 | K6: =COUNTBLANK(M4:M8)/2 -> 2.5 | L6: =K6*L2 -> 3.75 | N6: =COUNTBLANK(P4:P8)/2 -> 2.5 | O6: =N6*N2 -> 3.75 | S6: QUARTO 2 | AA6: P = Porta
E7: P | F7: =(B6+F2)*2 -> 15 | L7: =(K6+L2)*2 -> 8 | O7: =(N6+N2)*2 -> 8 | R7: Área: | S7: =Q2*W7 -> 10.5 | W7: =COUNTBLANK(X4:X10)/2 -> 3.5 | AA7: J = Janela
L8: P | O8: P | R8: P | S8: =(Q2+W7)*2 -> 13
J9: =COUNTBLANK(B9:B10)/2 -> 1 | K9: =L2*J9 -> 1.5 | N9: =N2*J9 -> 1.5 | AA9: Pé-direito: 2,80m
AA10: Escala: 1 célula = 0,5m
K12: P
F14: COZINHA | P14: SALA DE ESTAR
B15: =COUNTBLANK(J11:J19)/2 -> 4.5 | C15: J | V15: J | W15: =COUNTBLANK(K11:K19)/2 -> 4
E16: Área: | F16: =B15*F20 -> 18 | O16: Área: | P16: =W15*Q20 -> 24
E17: P | F17: =(F20+B15)*2 -> 17 | O17: P | P17: =(Q20+W15)*2 -> 20
F20: =COUNTBLANK(C19:J19)/2 -> 4 | Q20: =COUNTBLANK(K19:V19)/2 -> 6

Sheet 2 - Guia
A1: Item / Material | B1: Aplicação | C1: Regra de Rendimento / Observação do Fornecedor | D1: Preço Unitário | E1: Qtd a Comprar (Fórmula) | F1: Custo Total
A2: Piso Porcelanato 50x50 | B2: Salas, Corredor e Quartos | C2: 1 Caixa cobre 2,5 m². Adicionar 10% de margem para cortes. Apenas venda de caixa fechada. | D2: 145 | E2: =ROUNDUP(((AREASUITEMASTER+AREAQUARTO+AREASALAESTAR)*1.1/2.5),0) -> 22 | F2: =E2*D2 -> 3190
A3: Piso Cerâmico | B3: Cozinha e Banheiros | C3: 1 Caixa cobre 2,0 m². Adicionar 15% de margem para quebras. Apenas venda de caixa fechada. | D3: 85 | E3: =ROUNDUP(((AREAWC*2+AREACOZINHA)*1.15/2),0) -> 15 | F3: =E3*D3 -> 1275
A4: Tinta Acrílica Premium | B4: Paredes (Geral) | C4: 1 Lata (18L) pinta 100 m² (já contabilizando as 2 demãos necessárias). Apenas venda de lata inteira. | D4: 350 | E4: =(((PSUITEMASTER+PERIMQUARTO+PERIMETROSALA+PERIMCOSINHA)*2.8)/100)*18 -> 32.76 | F4: =E4*D4 -> 11466
A5: Tinta Antimofo | B5: Tetos (Banheiros) | C5: 1 Galão (3,6L) pinta 20 m². Apenas venda de galão inteiro. | D5: 95 | E5: =ROUNDUP((AREAWC*2)/20,0) -> 1 | F5: =E5*D5 -> 95
A6: Argamassa (Cimento Cola) | B6: Todos os Pisos | C6: 1 Saco (20kg) é suficiente para assentar 4 m² de piso. | D6: 35 | E6: =ROUNDUP((AREASUITEMASTER+AREAQUARTO+AREASALAESTAR+AREACOZINHA)/4,0) -> 17 | F6: =E6*D6 -> 595
A7: Rejunte | B7: Todos os Pisos | C7: 1 Pacote (1kg) rende 3 m² de piso finalizado. | D7: 18 | E7: =ROUNDUP((AREASUITEMASTER+AREAQUARTO+AREASALAESTAR+AREACOZINHA+AREAWC*2)/3,0) -> 25 | F7: =E7*D7 -> 450
A8: Rodapé em PVC/Madeira | B8: Salas e Quartos | C8: Vendido em barras de 2,5 metros lineares. Adicionar 10% para os cantos e cortes. | D8: 45 | E8: =ROUNDUP(((PSUITEMASTER+PERIMQUARTO+PERIMETROSALA)*1.1/2.5),0) -> 22 | F8: =E8*D8 -> 990
A11: DICA DO PROFESSOR ALESSANDRO:
A12: Lembrem-se da aula: Use a função =ARRED.PARA.CIMA() na coluna E para garantir que o Excel compre caixas e latas inteiras!

Sheet 3 - Orçamento
B1: ORÇAMENTO DETALHADO POR CÔMODO
B4: Item | C4: Ambiente | D4: Descrição do Material | E4: Unid. | F4: Quantidade | G4: Valor Unitário | H4: Subtotal
B5: 1. SUÍTE MASTER
B6: 1 | C6: SUÍTE MASTER | D6: Piso Porcelanato 50x50 | E6: cx | F6: =ROUNDUP((AREASUITEMASTER*1.1/2.5),0) -> 7 | G6: ='2 - Guia'!D2 -> 145 | H6: =F6*G6 -> 1015
B7: 2 | C7: SUÍTE MASTER | D7: Rodapé em Madeira | E7: br | F7: =ROUNDUP((PSUITEMASTER*1.1/2.5),0) -> 7 | G7: ='2 - Guia'!D8 -> 45 | H7: =F7*G7 -> 315
B8: 3 | C8: SUÍTE MASTER | D8: Tinta Acrílica Premium | E8: lt | F8: =((PSUITEMASTER*2.8)/100)*18 -> 7.56 | G8: ='2 - Guia'!D4 -> 350 | H8: =F8*G8 -> 2646
B9: 4 | C9: SUÍTE MASTER | D9: Argamassa (Cimento Cola) | E9: sc | F9: =ROUNDUP(AREASUITEMASTER/4,0) -> 4 | G9: ='2 - Guia'!D6 -> 35 | H9: =F9*G9 -> 140
B10: CUSTO TOTAL - SUÍTE MASTER: | H10: =SUM(H6:H9) -> 4116
B11: 2. WC SUÍTE E WC SOCIAL
B12: 1 | C12: WC SUÍTE E WC SOCIAL | D12: Piso Cerâmico | E12: cx | F12: =ROUNDUP((AREAWC*2*1.15/2),0) -> 5 | G12: ='2 - Guia'!D3 -> 85 | H12: =F12*G12 -> 425
B13: 2 | C13: WC SUÍTE E WC SOCIAL | D13: Revestimento de Parede | E13: cx | F13: =ROUNDUP((PERIMWC*2*2.5*1.15/2),0) -> 23 | G13: ='2 - Guia'!D3 -> 85 | H13: =F13*G13 -> 1955
B14: 3 | C14: WC SUÍTE E WC SOCIAL | D14: Tinta Antimofo (Teto) | E14: gl | F14: =ROUNDUP((AREAWC*2)/20,0) -> 1 | G14: ='2 - Guia'!D5 -> 95 | H14: =F14*G14 -> 95
B15: 4 | C15: WC SUÍTE E WC SOCIAL | D15: Argamassa (Cimento Cola) | E15: sc | F15: =ROUNDUP((AREAWC*2)/4,0) -> 2 | G15: ='2 - Guia'!D6 -> 35 | H15: =F15*G15 -> 70
B16: CUSTO TOTAL - WC SUÍTE E WC SOCIAL: | H16: =SUM(H12:H15) -> 2545
B17: 3. QUARTO 2
B18: 1 | C18: QUARTO 2 E QUARTO 3 | D18: Piso Porcelanato 50x50 | E18: cx | F18: =ROUNDUP((AREAQUARTO*1.1/2.5),0) -> 5 | G18: ='2 - Guia'!D2 -> 145 | H18: =F18*G18 -> 725
B19: 2 | C19: QUARTO 2 E QUARTO 3 | D19: Rodapé em Madeira | E19: br | F19: =ROUNDUP((PERIMQUARTO*1.1/2.5),0) -> 6 | G19: ='2 - Guia'!D8 -> 45 | H19: =F19*G19 -> 270
B20: 3 | C20: QUARTO 2 E QUARTO 3 | D20: Tinta Acrílica Premium | E20: lt | F20: =((PERIMQUARTO*2.8)/100)*18 -> 6.552 | G20: ='2 - Guia'!D4 -> 350 | H20: =F20*G20 -> 2293.2
B21: 4 | C21: QUARTO 2 E QUARTO 4 | D21: Argamassa (Cimento Cola) | E21: sc | F21: =ROUNDUP(AREAQUARTO/4,0) -> 3 | G21: ='2 - Guia'!D6 -> 35 | H21: =F21*G21 -> 105
B22: CUSTO TOTAL - QUARTO 2 E QUARTO 3: | H22: =SUM(H18:H21) -> 3393.2
B23: 4. SALA DE ESTAR / JANTAR
B24: 1 | C24: SALA DE ESTAR / JANTAR | D24: Piso Porcelanato 50x50 | E24: cx | F24: =ROUNDUP((AREASALAESTAR*1.1/2.5),0) -> 11 | G24: ='2 - Guia'!D2 -> 145 | H24: =F24*G24 -> 1595
B25: 2 | C25: SALA DE ESTAR / JANTAR | D25: Rodapé em Madeira | E25: br | F25: =ROUNDUP((PERIMETROSALA*1.1/2.5),0) -> 9 | G25: ='2 - Guia'!D8 -> 45 | H25: =F25*G25 -> 405
B26: 3 | C26: SALA DE ESTAR / JANTAR | D26: Tinta Acrílica Premium | E26: lt | F26: =((PERIMETROSALA*2.8)/100)*18 -> 10.08 | G26: ='2 - Guia'!D4 -> 350 | H26: =F26*G26 -> 3528
B27: 4 | C27: SALA DE ESTAR / JANTAR | D27: Argamassa (Cimento Cola) | E27: sc | F27: =ROUNDUP(AREASALAESTAR/4,0) -> 6 | G27: ='2 - Guia'!D6 -> 35 | H27: =F27*G27 -> 210
B28: CUSTO TOTAL - SALA DE ESTAR / JANTAR: | H28: =SUM(H24:H27) -> 5738
B29: 5. COZINHA
B30: 1 | C30: COZINHA | D30: Piso Cerâmico | E30: cx | F30: =ROUNDUP((AREACOZINHA*1.15/2),0) -> 11 | G30: ='2 - Guia'!D3 -> 85 | H30: =F30*G30 -> 935
B31: 2 | C31: COZINHA | D31: Revestimento de Parede | E31: cx | F31: =ROUNDUP((PERIMCOSINHA*2.5*1.15/2),0) -> 25 | G31: ='2 - Guia'!D3 -> 85 | H31: =F31*G31 -> 2125
B32: 4 | C32: COZINHA | D32: Argamassa (Cimento Cola) | E32: sc | F32: =ROUNDUP(AREACOZINHA/4,0) -> 5 | G32: ='2 - Guia'!D6 -> 35 | H32: =F32*G32 -> 175
B33: CUSTO TOTAL - COZINHA: | H33: =SUM(H30:H32) -> 3235
B34: CUSTO TOTAL DOS AMBIENTES: | H34: =SUM(H33,H28,H22,H16,H10) -> 19027.2
B37: 6. SUBTOTAL POR ITEM
B38: ITENS | D38: Piso Porcelanato 50x50 | E38: cx | F38: =SUM(F6,F18,F24) -> 23 | G38: 145 | H38: =F38*G38 -> 3335
D39: Rodapé em Madeira | E39: br | F39: =SUM(F7,F19,F25) -> 22 | G39: 45 | H39: =F39*G39 -> 990
D40: Tinta Acrílica Premium | E40: lt | F40: =SUM(F8,F20,F26) -> 24.192 | G40: 350 | H40: =F40*G40 -> 8467.2
D41: Argamassa (Cimento Cola) | E41: sc | F41: =SUM(F9,F15,F21,F27,F32) -> 20 | G41: 35 | H41: =F41*G41 -> 700
D42: Piso Cerâmico | E42: cx | F42: =SUM(F12,F30) -> 16 | G42: 85 | H42: =F42*G42 -> 1360
D43: Revestimento de Parede | E43: cx | F43: =SUM(F13,F31) -> 48 | G43: 85 | H43: =F43*G43 -> 4080
D44: Tinta Antimofo (Teto) | E44: gl | F44: =F14 -> 1 | G44: 95 | H44: =F44*G44 -> 95
...
